Workbook

Sheet Zone Area Matrix
A1: ZONE AREA DISTRIBUTION MATRIX
A2: Core Deduction: 15% | Structural Deduction: 15% | Net Usable = 70% of Gross
A4: ASSUMPTIONS
A5: Core % | B5: 0.15
A6: Structural % | B6: 0.15
A7: Net Usable % | B7: =1-B5-B6 -> 0.7
A9: ZONE | B9: GROSS AREA (m²) | C9: CORE AREA (m²) | D9: STRUCTURAL AREA (m²) | E9: TOTAL DEDUCTION (m²) | F9: NET USABLE AREA (m²) | G9: CORE % | H9: STRUCTURAL % | I9: NET %
A10: MEDICAL | B10: 35000 | C10: =B10*$B$5 -> 5250 | D10: =B10*$B$6 -> 5250 | E10: =C10+D10 -> 10500 | F10: =B10*$B$7 -> 24500 | G10: =$B$5 -> 0.15 | H10: =$B$6 -> 0.15 | I10: =$B$7 -> 0.7
A11: HOTEL | B11: 50000 | C11: =B11*$B$5 -> 7500 | D11: =B11*$B$6 -> 7500 | E11: =C11+D11 -> 15000 | F11: =B11*$B$7 -> 35000 | G11: =$B$5 -> 0.15 | H11: =$B$6 -> 0.15 | I11: =$B$7 -> 0.7
A12: TRANSPORTATION HQ | B12: 52000 | C12: =B12*$B$5 -> 7800 | D12: =B12*$B$6 -> 7800 | E12: =C12+D12 -> 15600 | F12: =B12*$B$7 -> 36400 | G12: =$B$5 -> 0.15 | H12: =$B$6 -> 0.15 | I12: =$B$7 -> 0.7
A13: CORPORATE OFFICE | B13: 30000 | C13: =B13*$B$5 -> 4500 | D13: =B13*$B$6 -> 4500 | E13: =C13+D13 -> 9000 | F13: =B13*$B$7 -> 21000 | G13: =$B$5 -> 0.15 | H13: =$B$6 -> 0.15 | I13: =$B$7 -> 0.7
A14: ADMIN OFFICE | B14: 30000 | C14: =B14*$B$5 -> 4500 | D14: =B14*$B$6 -> 4500 | E14: =C14+D14 -> 9000 | F14: =B14*$B$7 -> 21000 | G14: =$B$5 -> 0.15 | H14: =$B$6 -> 0.15 | I14: =$B$7 -> 0.7
A15: ENTERTAINMENT | B15: 31000 | C15: =B15*$B$5 -> 4650 | D15: =B15*$B$6 -> 4650 | E15: =C15+D15 -> 9300 | F15: =B15*$B$7 -> 21700 | G15: =$B$5 -> 0.15 | H15: =$B$6 -> 0.15 | I15: =$B$7 -> 0.7
A16: SKY ZONE | B16: 10400 | C16: =B16*$B$5 -> 1560 | D16: =B16*$B$6 -> 1560 | E16: =C16+D16 -> 3120 | F16: =B16*$B$7 -> 7280 | G16: =$B$5 -> 0.15 | H16: =$B$6 -> 0.15 | I16: =$B$7 -> 0.7
A17: TOTAL | B17: =SUM(B10:B16) -> 238400 | C17: =SUM(C10:C16) -> 35760 | D17: =SUM(D10:D16) -> 35760 | E17: =SUM(E10:E16) -> 71520 | F17: =SUM(F10:F16) -> 166880

Sheet Threshold Matrix
A1: PROGRAM THRESHOLD MATRIX — Input for Speckle Automate
A2: Max % = maximum share one program may occupy before the floor is flagged as mono-functional
A4: ZONE / PROGRAM | B4: GROSS AREA (m²) | C4: NET USABLE (m²) | D4: MAX % (Threshold) | E4: NOTES
A5: MEDICAL | B5: ='Zone Area Matrix'!B10 -> 35000 | C5: ='Zone Area Matrix'!F10 -> 24500 | D5: 0.75 | E5: Clinical + admin mix; no single use >75%
A6: HOTEL | B6: ='Zone Area Matrix'!B11 -> 50000 | C6: ='Zone Area Matrix'!F11 -> 35000 | D6: 0.8 | E6: Hotel keys dominant; F&B/support allowed up to 20%
A7: TRANSPORTATION HQ | B7: ='Zone Area Matrix'!B12 -> 52000 | C7: ='Zone Area Matrix'!F12 -> 36400 | D7: 0.7 | E7: Ops + office mix; mono-use flagged >70%
A8: CORPORATE OFFICE | B8: ='Zone Area Matrix'!B13 -> 30000 | C8: ='Zone Area Matrix'!F13 -> 21000 | D8: 0.75 | E8: Open-plan office; support uses <25%
A9: ADMIN OFFICE | B9: ='Zone Area Matrix'!B14 -> 30000 | C9: ='Zone Area Matrix'!F14 -> 21000 | D9: 0.75 | E9: Admin; breakout / meeting <25%
A10: ENTERTAINMENT | B10: ='Zone Area Matrix'!B15 -> 31000 | C10: ='Zone Area Matrix'!F15 -> 21700 | D10: 0.65 | E10: High diversity required; single use max 65%
A11: SKY ZONE | B11: ='Zone Area Matrix'!B16 -> 10400 | C11: ='Zone Area Matrix'!F16 -> 7280 | D11: 0.6 | E11: Observation + F&B; no single program >60%
A14: JSON FOR SPECKLE AUTOMATE → Copy the cell below into Input 4 (Program Threshold Matrix)
A15: {"MEDICAL": 75, "HOTEL": 80, "TRANSPORTATION HQ": 70, "CORPORATE OFFICE": 75, "ADMIN OFFICE": 75, "ENTERTAINMENT": 65, "SKY ZONE": 60}

Sheet Floor Breakdown
A1: FLOOR-BY-FLOOR AREA BREAKDOWN — Core 15% + Structural 15% per Floor
A2: Each floor's gross area = Zone Gross ÷ No. of Floors | Core = 15% | Structural = 15% | Net Usable = 70%
A4: Core % | B4: 0.15 | C4: Structural % | D4: 0.15 | E4: Net Usable % | F4: =1-B4-D4 -> 0.7
A6: ZONE / FLOOR | B6: FL # | C6: GROSS AREA / FLOOR (m²) | D6: CORE AREA (15%) (m²) | E6: STRUCTURAL (15%) (m²) | F6: TOTAL DEDUCTION (m²) | G6: NET USABLE (70%) (m²) | H6: CORE % | I6: STRUCT % | J6: NET %
A7: MEDICAL | B7: B1 | C7: =35000/5 -> 7000 | D7: =C7*$B$4 -> 1050 | E7: =C7*$D$4 -> 1050 | F7: =D7+E7 -> 2100 | G7: =C7*$F$4 -> 4900 | H7: =$B$4 -> 0.15 | I7: =$D$4 -> 0.15 | J7: =$F$4 -> 0.7
B8: B2 | C8: =35000/5 -> 7000 | D8: =C8*$B$4 -> 1050 | E8: =C8*$D$4 -> 1050 | F8: =D8+E8 -> 2100 | G8: =C8*$F$4 -> 4900 | H8: =$B$4 -> 0.15 | I8: =$D$4 -> 0.15 | J8: =$F$4 -> 0.7
B9: B3 | C9: =35000/5 -> 7000 | D9: =C9*$B$4 -> 1050 | E9: =C9*$D$4 -> 1050 | F9: =D9+E9 -> 2100 | G9: =C9*$F$4 -> 4900 | H9: =$B$4 -> 0.15 | I9: =$D$4 -> 0.15 | J9: =$F$4 -> 0.7
B10: B4 | C10: =35000/5 -> 7000 | D10: =C10*$B$4 -> 1050 | E10: =C10*$D$4 -> 1050 | F10: =D10+E10 -> 2100 | G10: =C10*$F$4 -> 4900 | H10: =$B$4 -> 0.15 | I10: =$D$4 -> 0.15 | J10: =$F$4 -> 0.7
B11: B5 | C11: =35000/5 -> 7000 | D11: =C11*$B$4 -> 1050 | E11: =C11*$D$4 -> 1050 | F11: =D11+E11 -> 2100 | G11: =C11*$F$4 -> 4900 | H11: =$B$4 -> 0.15 | I11: =$D$4 -> 0.15 | J11: =$F$4 -> 0.7
A12: ↳ MEDICAL TOTAL | B12: 5 fl. | C12: =SUM(C7:C11) -> 35000 | D12: =SUM(D7:D11) -> 5250 | E12: =SUM(E7:E11) -> 5250 | F12: =SUM(F7:F11) -> 10500 | G12: =SUM(G7:G11) -> 24500 | H12: =$B$4 -> 0.15 | I12: =$D$4 -> 0.15 | J12: =$F$4 -> 0.7
A14: HOTEL | B14: L1 | C14: =50000/12 -> 4166.6667 | D14: =C14*$B$4 -> 625 | E14: =C14*$D$4 -> 625 | F14: =D14+E14 -> 1250 | G14: =C14*$F$4 -> 2916.6667 | H14: =$B$4 -> 0.15 | I14: =$D$4 -> 0.15 | J14: =$F$4 -> 0.7
B15: L2 | C15: =50000/12 -> 4166.6667 | D15: =C15*$B$4 -> 625 | E15: =C15*$D$4 -> 625 | F15: =D15+E15 -> 1250 | G15: =C15*$F$4 -> 2916.6667 | H15: =$B$4 -> 0.15 | I15: =$D$4 -> 0.15 | J15: =$F$4 -> 0.7
B16: L3 | C16: =50000/12 -> 4166.6667 | D16: =C16*$B$4 -> 625 | E16: =C16*$D$4 -> 625 | F16: =D16+E16 -> 1250 | G16: =C16*$F$4 -> 2916.6667 | H16: =$B$4 -> 0.15 | I16: =$D$4 -> 0.15 | J16: =$F$4 -> 0.7
B17: L4 | C17: =50000/12 -> 4166.6667 | D17: =C17*$B$4 -> 625 | E17: =C17*$D$4 -> 625 | F17: =D17+E17 -> 1250 | G17: =C17*$F$4 -> 2916.6667 | H17: =$B$4 -> 0.15 | I17: =$D$4 -> 0.15 | J17: =$F$4 -> 0.7
B18: L5 | C18: =50000/12 -> 4166.6667 | D18: =C18*$B$4 -> 625 | E18: =C18*$D$4 -> 625 | F18: =D18+E18 -> 1250 | G18: =C18*$F$4 -> 2916.6667 | H18: =$B$4 -> 0.15 | I18: =$D$4 -> 0.15 | J18: =$F$4 -> 0.7
B19: L6 | C19: =50000/12 -> 4166.6667 | D19: =C19*$B$4 -> 625 | E19: =C19*$D$4 -> 625 | F19: =D19+E19 -> 1250 | G19: =C19*$F$4 -> 2916.6667 | H19: =$B$4 -> 0.15 | I19: =$D$4 -> 0.15 | J19: =$F$4 -> 0.7
B20: L7 | C20: =50000/12 -> 4166.6667 | D20: =C20*$B$4 -> 625 | E20: =C20*$D$4 -> 625 | F20: =D20+E20 -> 1250 | G20: =C20*$F$4 -> 2916.6667 | H20: =$B$4 -> 0.15 | I20: =$D$4 -> 0.15 | J20: =$F$4 -> 0.7
B21: L8 | C21: =50000/12 -> 4166.6667 | D21: =C21*$B$4 -> 625 | E21: =C21*$D$4 -> 625 | F21: =D21+E21 -> 1250 | G21: =C21*$F$4 -> 2916.6667 | H21: =$B$4 -> 0.15 | I21: =$D$4 -> 0.15 | J21: =$F$4 -> 0.7
B22: L9 | C22: =50000/12 -> 4166.6667 | D22: =C22*$B$4 -> 625 | E22: =C22*$D$4 -> 625 | F22: =D22+E22 -> 1250 | G22: =C22*$F$4 -> 2916.6667 | H22: =$B$4 -> 0.15 | I22: =$D$4 -> 0.15 | J22: =$F$4 -> 0.7
B23: L10 | C23: =50000/12 -> 4166.6667 | D23: =C23*$B$4 -> 625 | E23: =C23*$D$4 -> 625 | F23: =D23+E23 -> 1250 | G23: =C23*$F$4 -> 2916.6667 | H23: =$B$4 -> 0.15 | I23: =$D$4 -> 0.15 | J23: =$F$4 -> 0.7
B24: L11 | C24: =50000/12 -> 4166.6667 | D24: =C24*$B$4 -> 625 | E24: =C24*$D$4 -> 625 | F24: =D24+E24 -> 1250 | G24: =C24*$F$4 -> 2916.6667 | H24: =$B$4 -> 0.15 | I24: =$D$4 -> 0.15 | J24: =$F$4 -> 0.7
B25: L12 | C25: =50000/12 -> 4166.6667 | D25: =C25*$B$4 -> 625 | E25: =C25*$D$4 -> 625 | F25: =D25+E25 -> 1250 | G25: =C25*$F$4 -> 2916.6667 | H25: =$B$4 -> 0.15 | I25: =$D$4 -> 0.15 | J25: =$F$4 -> 0.7
A26: ↳ HOTEL TOTAL | B26: 12 fl. | C26: =SUM(C14:C25) -> 50000 | D26: =SUM(D14:D25) -> 7500 | E26: =SUM(E14:E25) -> 7500 | F26: =SUM(F14:F25) -> 15000 | G26: =SUM(G14:G25) -> 35000 | H26: =$B$4 -> 0.15 | I26: =$D$4 -> 0.15 | J26: =$F$4 -> 0.7
A28: TRANSPORTATION HQ | B28: T1 | C28: =52000/8 -> 6500 | D28: =C28*$B$4 -> 975 | E28: =C28*$D$4 -> 975 | F28: =D28+E28 -> 1950 | G28: =C28*$F$4 -> 4550 | H28: =$B$4 -> 0.15 | I28: =$D$4 -> 0.15 | J28: =$F$4 -> 0.7
B29: T2 | C29: =52000/8 -> 6500 | D29: =C29*$B$4 -> 975 | E29: =C29*$D$4 -> 975 | F29: =D29+E29 -> 1950 | G29: =C29*$F$4 -> 4550 | H29: =$B$4 -> 0.15 | I29: =$D$4 -> 0.15 | J29: =$F$4 -> 0.7
B30: T3 | C30: =52000/8 -> 6500 | D30: =C30*$B$4 -> 975 | E30: =C30*$D$4 -> 975 | F30: =D30+E30 -> 1950 | G30: =C30*$F$4 -> 4550 | H30: =$B$4 -> 0.15 | I30: =$D$4 -> 0.15 | J30: =$F$4 -> 0.7
B31: T4 | C31: =52000/8 -> 6500 | D31: =C31*$B$4 -> 975 | E31: =C31*$D$4 -> 975 | F31: =D31+E31 -> 1950 | G31: =C31*$F$4 -> 4550 | H31: =$B$4 -> 0.15 | I31: =$D$4 -> 0.15 | J31: =$F$4 -> 0.7
B32: T5 | C32: =52000/8 -> 6500 | D32: =C32*$B$4 -> 975 | E32: =C32*$D$4 -> 975 | F32: =D32+E32 -> 1950 | G32: =C32*$F$4 -> 4550 | H32: =$B$4 -> 0.15 | I32: =$D$4 -> 0.15 | J32: =$F$4 -> 0.7
B33: T6 | C33: =52000/8 -> 6500 | D33: =C33*$B$4 -> 975 | E33: =C33*$D$4 -> 975 | F33: =D33+E33 -> 1950 | G33: =C33*$F$4 -> 4550 | H33: =$B$4 -> 0.15 | I33: =$D$4 -> 0.15 | J33: =$F$4 -> 0.7
B34: T7 | C34: =52000/8 -> 6500 | D34: =C34*$B$4 -> 975 | E34: =C34*$D$4 -> 975 | F34: =D34+E34 -> 1950 | G34: =C34*$F$4 -> 4550 | H34: =$B$4 -> 0.15 | I34: =$D$4 -> 0.15 | J34: =$F$4 -> 0.7
B35: T8 | C35: =52000/8 -> 6500 | D35: =C35*$B$4 -> 975 | E35: =C35*$D$4 -> 975 | F35: =D35+E35 -> 1950 | G35: =C35*$F$4 -> 4550 | H35: =$B$4 -> 0.15 | I35: =$D$4 -> 0.15 | J35: =$F$4 -> 0.7
A36: ↳ TRANSPORTATION HQ TOTAL | B36: 8 fl. | C36: =SUM(C28:C35) -> 52000 | D36: =SUM(D28:D35) -> 7800 | E36: =SUM(E28:E35) -> 7800 | F36: =SUM(F28:F35) -> 15600 | G36: =SUM(G28:G35) -> 36400 | H36: =$B$4 -> 0.15 | I36: =$D$4 -> 0.15 | J36: =$F$4 -> 0.7
A38: CORPORATE OFFICE | B38: C1 | C38: =30000/10 -> 3000 | D38: =C38*$B$4 -> 450 | E38: =C38*$D$4 -> 450 | F38: =D38+E38 -> 900 | G38: =C38*$F$4 -> 2100 | H38: =$B$4 -> 0.15 | I38: =$D$4 -> 0.15 | J38: =$F$4 -> 0.7
B39: C2 | C39: =30000/10 -> 3000 | D39: =C39*$B$4 -> 450 | E39: =C39*$D$4 -> 450 | F39: =D39+E39 -> 900 | G39: =C39*$F$4 -> 2100 | H39: =$B$4 -> 0.15 | I39: =$D$4 -> 0.15 | J39: =$F$4 -> 0.7
B40: C3 | C40: =30000/10 -> 3000 | D40: =C40*$B$4 -> 450 | E40: =C40*$D$4 -> 450 | F40: =D40+E40 -> 900 | G40: =C40*$F$4 -> 2100 | H40: =$B$4 -> 0.15 | I40: =$D$4 -> 0.15 | J40: =$F$4 -> 0.7
B41: C4 | C41: =30000/10 -> 3000 | D41: =C41*$B$4 -> 450 | E41: =C41*$D$4 -> 450 | F41: =D41+E41 -> 900 | G41: =C41*$F$4 -> 2100 | H41: =$B$4 -> 0.15 | I41: =$D$4 -> 0.15 | J41: =$F$4 -> 0.7
B42: C5 | C42: =30000/10 -> 3000 | D42: =C42*$B$4 -> 450 | E42: =C42*$D$4 -> 450 | F42: =D42+E42 -> 900 | G42: =C42*$F$4 -> 2100 | H42: =$B$4 -> 0.15 | I42: =$D$4 -> 0.15 | J42: =$F$4 -> 0.7
B43: C6 | C43: =30000/10 -> 3000 | D43: =C43*$B$4 -> 450 | E43: =C43*$D$4 -> 450 | F43: =D43+E43 -> 900 | G43: =C43*$F$4 -> 2100 | H43: =$B$4 -> 0.15 | I43: =$D$4 -> 0.15 | J43: =$F$4 -> 0.7
B44: C7 | C44: =30000/10 -> 3000 | D44: =C44*$B$4 -> 450 | E44: =C44*$D$4 -> 450 | F44: =D44+E44 -> 900 | G44: =C44*$F$4 -> 2100 | H44: =$B$4 -> 0.15 | I44: =$D$4 -> 0.15 | J44: =$F$4 -> 0.7
B45: C8 | C45: =30000/10 -> 3000 | D45: =C45*$B$4 -> 450 | E45: =C45*$D$4 -> 450 | F45: =D45+E45 -> 900 | G45: =C45*$F$4 -> 2100 | H45: =$B$4 -> 0.15 | I45: =$D$4 -> 0.15 | J45: =$F$4 -> 0.7
...

Sheet Floor Area Estimator
A1: FLOOR AREA ESTIMATOR — Floors per Zone
A2: Enter number of floors per zone → area per floor and cumulative areas calculate automatically
A4: ZONE | B4: GROSS AREA (m²) | C4: NET USABLE (m²) | D4: NO. OF FLOORS | E4: GROSS / FLOOR (m²) | F4: NET / FLOOR (m²) | G4: CORE / FLOOR (m²) | H4: STRUCTURAL / FLOOR (m²)
A5: MEDICAL | B5: ='Zone Area Matrix'!B10 -> 35000 | C5: ='Zone Area Matrix'!F10 -> 24500 | D5: 5 | E5: =B5/D5 -> 7000 | F5: =C5/D5 -> 4900 | G5: =B5*'Zone Area Matrix'!$B$5/D5 -> 1050 | H5: =B5*'Zone Area Matrix'!$B$6/D5 -> 1050
A6: HOTEL | B6: ='Zone Area Matrix'!B11 -> 50000 | C6: ='Zone Area Matrix'!F11 -> 35000 | D6: 12 | E6: =B6/D6 -> 4166.6667 | F6: =C6/D6 -> 2916.6667 | G6: =B6*'Zone Area Matrix'!$B$5/D6 -> 625 | H6: =B6*'Zone Area Matrix'!$B$6/D6 -> 625
A7: TRANSPORTATION HQ | B7: ='Zone Area Matrix'!B12 -> 52000 | C7: ='Zone Area Matrix'!F12 -> 36400 | D7: 8 | E7: =B7/D7 -> 6500 | F7: =C7/D7 -> 4550 | G7: =B7*'Zone Area Matrix'!$B$5/D7 -> 975 | H7: =B7*'Zone Area Matrix'!$B$6/D7 -> 975
A8: CORPORATE OFFICE | B8: ='Zone Area Matrix'!B13 -> 30000 | C8: ='Zone Area Matrix'!F13 -> 21000 | D8: 10 | E8: =B8/D8 -> 3000 | F8: =C8/D8 -> 2100 | G8: =B8*'Zone Area Matrix'!$B$5/D8 -> 450 | H8: =B8*'Zone Area Matrix'!$B$6/D8 -> 450
A9: ADMIN OFFICE | B9: ='Zone Area Matrix'!B14 -> 30000 | C9: ='Zone Area Matrix'!F14 -> 21000 | D9: 8 | E9: =B9/D9 -> 3750 | F9: =C9/D9 -> 2625 | G9: =B9*'Zone Area Matrix'!$B$5/D9 -> 562.5 | H9: =B9*'Zone Area Matrix'!$B$6/D9 -> 562.5
A10: ENTERTAINMENT | B10: ='Zone Area Matrix'!B15 -> 31000 | C10: ='Zone Area Matrix'!F15 -> 21700 | D10: 6 | E10: =B10/D10 -> 5166.6667 | F10: =C10/D10 -> 3616.6667 | G10: =B10*'Zone Area Matrix'!$B$5/D10 -> 775 | H10: =B10*'Zone Area Matrix'!$B$6/D10 -> 775
A11: SKY ZONE | B11: ='Zone Area Matrix'!B16 -> 10400 | C11: ='Zone Area Matrix'!F16 -> 7280 | D11: 3 | E11: =B11/D11 -> 3466.6667 | F11: =C11/D11 -> 2426.6667 | G11: =B11*'Zone Area Matrix'!$B$5/D11 -> 520 | H11: =B11*'Zone Area Matrix'!$B$6/D11 -> 520
A12: TOTAL / AVG | B12: =SUM(B5:B11) -> 238400 | C12: =SUM(C5:C11) -> 166880 | D12: =SUM(D5:D11) -> 52 | E12: =AVERAGE(E5:E11) -> 4721.4286 | F12: =AVERAGE(F5:F11) -> 3305 | G12: =AVERAGE(G5:G11) -> 708.21429 | H12: =AVERAGE(H5:H11) -> 708.21429
